Not Found: /favicon.ico
Bad Request: /api/getProducts/
Bad Request: /api/getProducts/
Bad Request: /api/getProducts/
Bad Request: /api/getProducts/
Bad Request: /api/getProducts/
Bad Request: /api/getProducts/
Internal Server Error: /api/getProducts/
Traceback (most recent call last):
  File "/home/dani/gamingzone/ven/lib/python3.10/site-packages/django/db/backends/utils.py", line 89, in _execute
    return self.cursor.execute(sql, params)
psycopg2.errors.InvalidTextRepresentation: invalid input syntax for type json
LINE 1: ... NULL, 'frdsf', 'https://chatgpthttps.com', NULL, 'zef', 'ez...
                                                             ^
DETAIL:  Token "zef" is invalid.
CONTEXT:  JSON data, line 1: zef


The above exception was the direct cause of the following exception:

Traceback (most recent call last):
  File "/home/dani/gamingzone/ven/lib/python3.10/site-packages/django/core/handlers/exception.py", line 55, in inner
    response = get_response(request)
  File "/home/dani/gamingzone/ven/lib/python3.10/site-packages/django/core/handlers/base.py", line 197, in _get_response
    response = wrapped_callback(request, *callback_args, **callback_kwargs)
  File "/home/dani/gamingzone/ven/lib/python3.10/site-packages/django/views/decorators/csrf.py", line 56, in wrapper_view
    return view_func(*args, **kwargs)
  File "/home/dani/gamingzone/ven/lib/python3.10/site-packages/rest_framework/viewsets.py", line 124, in view
    return self.dispatch(request, *args, **kwargs)
  File "/home/dani/gamingzone/ven/lib/python3.10/site-packages/rest_framework/views.py", line 509, in dispatch
    response = self.handle_exception(exc)
  File "/home/dani/gamingzone/ven/lib/python3.10/site-packages/rest_framework/views.py", line 469, in handle_exception
    self.raise_uncaught_exception(exc)
  File "/home/dani/gamingzone/ven/lib/python3.10/site-packages/rest_framework/views.py", line 480, in raise_uncaught_exception
    raise exc
  File "/home/dani/gamingzone/ven/lib/python3.10/site-packages/rest_framework/views.py", line 506, in dispatch
    response = handler(request, *args, **kwargs)
  File "/home/dani/gamingzone/ven/lib/python3.10/site-packages/rest_framework/mixins.py", line 19, in create
    self.perform_create(serializer)
  File "/home/dani/gamingzone/ven/lib/python3.10/site-packages/rest_framework/mixins.py", line 24, in perform_create
    serializer.save()
  File "/home/dani/gamingzone/ven/lib/python3.10/site-packages/rest_framework/serializers.py", line 208, in save
    self.instance = self.create(validated_data)
  File "/home/dani/gamingzone/ven/lib/python3.10/site-packages/rest_framework/serializers.py", line 989, in create
    instance = ModelClass._default_manager.create(**validated_data)
  File "/home/dani/gamingzone/ven/lib/python3.10/site-packages/django/db/models/manager.py", line 87, in manager_method
    return getattr(self.get_queryset(), name)(*args, **kwargs)
  File "/home/dani/gamingzone/ven/lib/python3.10/site-packages/django/db/models/query.py", line 658, in create
    obj.save(force_insert=True, using=self.db)
  File "/home/dani/gamingzone/ven/lib/python3.10/site-packages/modelcluster/models.py", line 202, in save
    super().save(update_fields=real_update_fields, **kwargs)
  File "/home/dani/gamingzone/ven/lib/python3.10/site-packages/django/db/models/base.py", line 814, in save
    self.save_base(
  File "/home/dani/gamingzone/ven/lib/python3.10/site-packages/django/db/models/base.py", line 877, in save_base
    updated = self._save_table(
  File "/home/dani/gamingzone/ven/lib/python3.10/site-packages/django/db/models/base.py", line 1020, in _save_table
    results = self._do_insert(
  File "/home/dani/gamingzone/ven/lib/python3.10/site-packages/django/db/models/base.py", line 1061, in _do_insert
    return manager._insert(
  File "/home/dani/gamingzone/ven/lib/python3.10/site-packages/django/db/models/manager.py", line 87, in manager_method
    return getattr(self.get_queryset(), name)(*args, **kwargs)
  File "/home/dani/gamingzone/ven/lib/python3.10/site-packages/django/db/models/query.py", line 1805, in _insert
    return query.get_compiler(using=using).execute_sql(returning_fields)
  File "/home/dani/gamingzone/ven/lib/python3.10/site-packages/django/db/models/sql/compiler.py", line 1822, in execute_sql
    cursor.execute(sql, params)
  File "/home/dani/gamingzone/ven/lib/python3.10/site-packages/django/db/backends/utils.py", line 102, in execute
    return super().execute(sql, params)
  File "/home/dani/gamingzone/ven/lib/python3.10/site-packages/django/db/backends/utils.py", line 67, in execute
    return self._execute_with_wrappers(
  File "/home/dani/gamingzone/ven/lib/python3.10/site-packages/django/db/backends/utils.py", line 80, in _execute_with_wrappers
    return executor(sql, params, many, context)
  File "/home/dani/gamingzone/ven/lib/python3.10/site-packages/django/db/backends/utils.py", line 84, in _execute
    with self.db.wrap_database_errors:
  File "/home/dani/gamingzone/ven/lib/python3.10/site-packages/django/db/utils.py", line 91, in __exit__
    raise dj_exc_value.with_traceback(traceback) from exc_value
  File "/home/dani/gamingzone/ven/lib/python3.10/site-packages/django/db/backends/utils.py", line 89, in _execute
    return self.cursor.execute(sql, params)
django.db.utils.DataError: invalid input syntax for type json
LINE 1: ... NULL, 'frdsf', 'https://chatgpthttps.com', NULL, 'zef', 'ez...
                                                             ^
DETAIL:  Token "zef" is invalid.
CONTEXT:  JSON data, line 1: zef

Internal Server Error: /api/getProducts/
Traceback (most recent call last):
  File "/home/dani/gamingzone/ven/lib/python3.10/site-packages/django/db/backends/utils.py", line 89, in _execute
    return self.cursor.execute(sql, params)
psycopg2.errors.InvalidTextRepresentation: invalid input syntax for type json
LINE 1: ... NULL, 'frdsf', 'https://chatgpthttps.com', NULL, 'zef', 'ez...
                                                             ^
DETAIL:  Token "zef" is invalid.
CONTEXT:  JSON data, line 1: zef


The above exception was the direct cause of the following exception:

Traceback (most recent call last):
  File "/home/dani/gamingzone/ven/lib/python3.10/site-packages/django/core/handlers/exception.py", line 55, in inner
    response = get_response(request)
  File "/home/dani/gamingzone/ven/lib/python3.10/site-packages/django/core/handlers/base.py", line 197, in _get_response
    response = wrapped_callback(request, *callback_args, **callback_kwargs)
  File "/home/dani/gamingzone/ven/lib/python3.10/site-packages/django/views/decorators/csrf.py", line 56, in wrapper_view
    return view_func(*args, **kwargs)
  File "/home/dani/gamingzone/ven/lib/python3.10/site-packages/rest_framework/viewsets.py", line 124, in view
    return self.dispatch(request, *args, **kwargs)
  File "/home/dani/gamingzone/ven/lib/python3.10/site-packages/rest_framework/views.py", line 509, in dispatch
    response = self.handle_exception(exc)
  File "/home/dani/gamingzone/ven/lib/python3.10/site-packages/rest_framework/views.py", line 469, in handle_exception
    self.raise_uncaught_exception(exc)
  File "/home/dani/gamingzone/ven/lib/python3.10/site-packages/rest_framework/views.py", line 480, in raise_uncaught_exception
    raise exc
  File "/home/dani/gamingzone/ven/lib/python3.10/site-packages/rest_framework/views.py", line 506, in dispatch
    response = handler(request, *args, **kwargs)
  File "/home/dani/gamingzone/ven/lib/python3.10/site-packages/rest_framework/mixins.py", line 19, in create
    self.perform_create(serializer)
  File "/home/dani/gamingzone/ven/lib/python3.10/site-packages/rest_framework/mixins.py", line 24, in perform_create
    serializer.save()
  File "/home/dani/gamingzone/ven/lib/python3.10/site-packages/rest_framework/serializers.py", line 208, in save
    self.instance = self.create(validated_data)
  File "/home/dani/gamingzone/ven/lib/python3.10/site-packages/rest_framework/serializers.py", line 989, in create
    instance = ModelClass._default_manager.create(**validated_data)
  File "/home/dani/gamingzone/ven/lib/python3.10/site-packages/django/db/models/manager.py", line 87, in manager_method
    return getattr(self.get_queryset(), name)(*args, **kwargs)
  File "/home/dani/gamingzone/ven/lib/python3.10/site-packages/django/db/models/query.py", line 658, in create
    obj.save(force_insert=True, using=self.db)
  File "/home/dani/gamingzone/ven/lib/python3.10/site-packages/modelcluster/models.py", line 202, in save
    super().save(update_fields=real_update_fields, **kwargs)
  File "/home/dani/gamingzone/ven/lib/python3.10/site-packages/django/db/models/base.py", line 814, in save
    self.save_base(
  File "/home/dani/gamingzone/ven/lib/python3.10/site-packages/django/db/models/base.py", line 877, in save_base
    updated = self._save_table(
  File "/home/dani/gamingzone/ven/lib/python3.10/site-packages/django/db/models/base.py", line 1020, in _save_table
    results = self._do_insert(
  File "/home/dani/gamingzone/ven/lib/python3.10/site-packages/django/db/models/base.py", line 1061, in _do_insert
    return manager._insert(
  File "/home/dani/gamingzone/ven/lib/python3.10/site-packages/django/db/models/manager.py", line 87, in manager_method
    return getattr(self.get_queryset(), name)(*args, **kwargs)
  File "/home/dani/gamingzone/ven/lib/python3.10/site-packages/django/db/models/query.py", line 1805, in _insert
    return query.get_compiler(using=using).execute_sql(returning_fields)
  File "/home/dani/gamingzone/ven/lib/python3.10/site-packages/django/db/models/sql/compiler.py", line 1822, in execute_sql
    cursor.execute(sql, params)
  File "/home/dani/gamingzone/ven/lib/python3.10/site-packages/django/db/backends/utils.py", line 102, in execute
    return super().execute(sql, params)
  File "/home/dani/gamingzone/ven/lib/python3.10/site-packages/django/db/backends/utils.py", line 67, in execute
    return self._execute_with_wrappers(
  File "/home/dani/gamingzone/ven/lib/python3.10/site-packages/django/db/backends/utils.py", line 80, in _execute_with_wrappers
    return executor(sql, params, many, context)
  File "/home/dani/gamingzone/ven/lib/python3.10/site-packages/django/db/backends/utils.py", line 84, in _execute
    with self.db.wrap_database_errors:
  File "/home/dani/gamingzone/ven/lib/python3.10/site-packages/django/db/utils.py", line 91, in __exit__
    raise dj_exc_value.with_traceback(traceback) from exc_value
  File "/home/dani/gamingzone/ven/lib/python3.10/site-packages/django/db/backends/utils.py", line 89, in _execute
    return self.cursor.execute(sql, params)
django.db.utils.DataError: invalid input syntax for type json
LINE 1: ... NULL, 'frdsf', 'https://chatgpthttps.com', NULL, 'zef', 'ez...
                                                             ^
DETAIL:  Token "zef" is invalid.
CONTEXT:  JSON data, line 1: zef

Internal Server Error: /django-admin/backendAPI/product/add/
Traceback (most recent call last):
  File "/home/dani/gamingzone/ven/lib/python3.10/site-packages/django/utils/datastructures.py", line 84, in __getitem__
    list_ = super().__getitem__(key)
KeyError: 'body-count'

During handling of the above exception, another exception occurred:

Traceback (most recent call last):
  File "/home/dani/gamingzone/ven/lib/python3.10/site-packages/django/core/handlers/exception.py", line 55, in inner
    response = get_response(request)
  File "/home/dani/gamingzone/ven/lib/python3.10/site-packages/django/core/handlers/base.py", line 197, in _get_response
    response = wrapped_callback(request, *callback_args, **callback_kwargs)
  File "/home/dani/gamingzone/ven/lib/python3.10/site-packages/django/contrib/admin/options.py", line 688, in wrapper
    return self.admin_site.admin_view(view)(*args, **kwargs)
  File "/home/dani/gamingzone/ven/lib/python3.10/site-packages/django/utils/decorators.py", line 134, in _wrapper_view
    response = view_func(request, *args, **kwargs)
  File "/home/dani/gamingzone/ven/lib/python3.10/site-packages/django/views/decorators/cache.py", line 62, in _wrapper_view_func
    response = view_func(request, *args, **kwargs)
  File "/home/dani/gamingzone/ven/lib/python3.10/site-packages/django/contrib/admin/sites.py", line 242, in inner
    return view(request, *args, **kwargs)
  File "/home/dani/gamingzone/ven/lib/python3.10/site-packages/django/contrib/admin/options.py", line 1886, in add_view
    return self.changeform_view(request, None, form_url, extra_context)
  File "/home/dani/gamingzone/ven/lib/python3.10/site-packages/django/utils/decorators.py", line 46, in _wrapper
    return bound_method(*args, **kwargs)
  File "/home/dani/gamingzone/ven/lib/python3.10/site-packages/django/utils/decorators.py", line 134, in _wrapper_view
    response = view_func(request, *args, **kwargs)
  File "/home/dani/gamingzone/ven/lib/python3.10/site-packages/django/contrib/admin/options.py", line 1747, in changeform_view
    return self._changeform_view(request, object_id, form_url, extra_context)
  File "/home/dani/gamingzone/ven/lib/python3.10/site-packages/django/contrib/admin/options.py", line 1792, in _changeform_view
    form_validated = form.is_valid()
  File "/home/dani/gamingzone/ven/lib/python3.10/site-packages/django/forms/forms.py", line 201, in is_valid
    return self.is_bound and not self.errors
  File "/home/dani/gamingzone/ven/lib/python3.10/site-packages/django/forms/forms.py", line 196, in errors
    self.full_clean()
  File "/home/dani/gamingzone/ven/lib/python3.10/site-packages/django/forms/forms.py", line 433, in full_clean
    self._clean_fields()
  File "/home/dani/gamingzone/ven/lib/python3.10/site-packages/django/forms/forms.py", line 440, in _clean_fields
    value = bf.initial if field.disabled else bf.data
  File "/home/dani/gamingzone/ven/lib/python3.10/site-packages/django/forms/boundfield.py", line 135, in data
    return self.form._widget_data_value(self.field.widget, self.html_name)
  File "/home/dani/gamingzone/ven/lib/python3.10/site-packages/django/forms/forms.py", line 220, in _widget_data_value
    return widget.value_from_datadict(self.data, self.files, html_name)
  File "/home/dani/gamingzone/ven/lib/python3.10/site-packages/wagtail/blocks/base.py", line 577, in value_from_datadict
    return self.block_def.value_from_datadict(data, files, name)
  File "/home/dani/gamingzone/ven/lib/python3.10/site-packages/wagtail/blocks/stream_block.py", line 116, in value_from_datadict
    count = int(data["%s-count" % prefix])
  File "/home/dani/gamingzone/ven/lib/python3.10/site-packages/django/utils/datastructures.py", line 86, in __getitem__
    raise MultiValueDictKeyError(key)
django.utils.datastructures.MultiValueDictKeyError: 'body-count'
Internal Server Error: /django-admin/backendAPI/product/add/
Traceback (most recent call last):
  File "/home/dani/gamingzone/ven/lib/python3.10/site-packages/django/utils/datastructures.py", line 84, in __getitem__
    list_ = super().__getitem__(key)
KeyError: 'body-count'

During handling of the above exception, another exception occurred:

Traceback (most recent call last):
  File "/home/dani/gamingzone/ven/lib/python3.10/site-packages/django/core/handlers/exception.py", line 55, in inner
    response = get_response(request)
  File "/home/dani/gamingzone/ven/lib/python3.10/site-packages/django/core/handlers/base.py", line 197, in _get_response
    response = wrapped_callback(request, *callback_args, **callback_kwargs)
  File "/home/dani/gamingzone/ven/lib/python3.10/site-packages/django/contrib/admin/options.py", line 688, in wrapper
    return self.admin_site.admin_view(view)(*args, **kwargs)
  File "/home/dani/gamingzone/ven/lib/python3.10/site-packages/django/utils/decorators.py", line 134, in _wrapper_view
    response = view_func(request, *args, **kwargs)
  File "/home/dani/gamingzone/ven/lib/python3.10/site-packages/django/views/decorators/cache.py", line 62, in _wrapper_view_func
    response = view_func(request, *args, **kwargs)
  File "/home/dani/gamingzone/ven/lib/python3.10/site-packages/django/contrib/admin/sites.py", line 242, in inner
    return view(request, *args, **kwargs)
  File "/home/dani/gamingzone/ven/lib/python3.10/site-packages/django/contrib/admin/options.py", line 1886, in add_view
    return self.changeform_view(request, None, form_url, extra_context)
  File "/home/dani/gamingzone/ven/lib/python3.10/site-packages/django/utils/decorators.py", line 46, in _wrapper
    return bound_method(*args, **kwargs)
  File "/home/dani/gamingzone/ven/lib/python3.10/site-packages/django/utils/decorators.py", line 134, in _wrapper_view
    response = view_func(request, *args, **kwargs)
  File "/home/dani/gamingzone/ven/lib/python3.10/site-packages/django/contrib/admin/options.py", line 1747, in changeform_view
    return self._changeform_view(request, object_id, form_url, extra_context)
  File "/home/dani/gamingzone/ven/lib/python3.10/site-packages/django/contrib/admin/options.py", line 1792, in _changeform_view
    form_validated = form.is_valid()
  File "/home/dani/gamingzone/ven/lib/python3.10/site-packages/django/forms/forms.py", line 201, in is_valid
    return self.is_bound and not self.errors
  File "/home/dani/gamingzone/ven/lib/python3.10/site-packages/django/forms/forms.py", line 196, in errors
    self.full_clean()
  File "/home/dani/gamingzone/ven/lib/python3.10/site-packages/django/forms/forms.py", line 433, in full_clean
    self._clean_fields()
  File "/home/dani/gamingzone/ven/lib/python3.10/site-packages/django/forms/forms.py", line 440, in _clean_fields
    value = bf.initial if field.disabled else bf.data
  File "/home/dani/gamingzone/ven/lib/python3.10/site-packages/django/forms/boundfield.py", line 135, in data
    return self.form._widget_data_value(self.field.widget, self.html_name)
  File "/home/dani/gamingzone/ven/lib/python3.10/site-packages/django/forms/forms.py", line 220, in _widget_data_value
    return widget.value_from_datadict(self.data, self.files, html_name)
  File "/home/dani/gamingzone/ven/lib/python3.10/site-packages/wagtail/blocks/base.py", line 577, in value_from_datadict
    return self.block_def.value_from_datadict(data, files, name)
  File "/home/dani/gamingzone/ven/lib/python3.10/site-packages/wagtail/blocks/stream_block.py", line 116, in value_from_datadict
    count = int(data["%s-count" % prefix])
  File "/home/dani/gamingzone/ven/lib/python3.10/site-packages/django/utils/datastructures.py", line 86, in __getitem__
    raise MultiValueDictKeyError(key)
django.utils.datastructures.MultiValueDictKeyError: 'body-count'
/home/dani/gamingzone/ven/lib/python3.10/site-packages/django/views/debug.py:487: ExceptionCycleWarning: Cycle in the exception chain detected: exception 'Error 111 connecting to 127.0.0.1:6379. Connection refused.' encountered again.
  warnings.warn(
Internal Server Error: /api/getProducts/
Traceback (most recent call last):
  File "/home/dani/gamingzone/ven/lib/python3.10/site-packages/django_redis/cache.py", line 29, in _decorator
    return method(self, *args, **kwargs)
  File "/home/dani/gamingzone/ven/lib/python3.10/site-packages/django_redis/cache.py", line 99, in _get
    return self.client.get(key, default=default, version=version, client=client)
  File "/home/dani/gamingzone/ven/lib/python3.10/site-packages/django_redis/client/default.py", line 260, in get
    raise ConnectionInterrupted(connection=client) from e
django_redis.exceptions.ConnectionInterrupted: Redis ConnectionError: Error 111 connecting to 127.0.0.1:6379. Connection refused.

During handling of the above exception, another exception occurred:

Traceback (most recent call last):
  File "/home/dani/gamingzone/ven/lib/python3.10/site-packages/django/core/handlers/exception.py", line 55, in inner
    response = get_response(request)
  File "/home/dani/gamingzone/ven/lib/python3.10/site-packages/django/core/handlers/base.py", line 197, in _get_response
    response = wrapped_callback(request, *callback_args, **callback_kwargs)
  File "/home/dani/gamingzone/ven/lib/python3.10/site-packages/django/views/decorators/csrf.py", line 56, in wrapper_view
    return view_func(*args, **kwargs)
  File "/home/dani/gamingzone/ven/lib/python3.10/site-packages/rest_framework/viewsets.py", line 124, in view
    return self.dispatch(request, *args, **kwargs)
  File "/home/dani/gamingzone/ven/lib/python3.10/site-packages/rest_framework/views.py", line 509, in dispatch
    response = self.handle_exception(exc)
  File "/home/dani/gamingzone/ven/lib/python3.10/site-packages/rest_framework/views.py", line 469, in handle_exception
    self.raise_uncaught_exception(exc)
  File "/home/dani/gamingzone/ven/lib/python3.10/site-packages/rest_framework/views.py", line 480, in raise_uncaught_exception
    raise exc
  File "/home/dani/gamingzone/ven/lib/python3.10/site-packages/rest_framework/views.py", line 506, in dispatch
    response = handler(request, *args, **kwargs)
  File "/home/dani/gamingzone/gamingzo/gzBackend/backendAPI/views.py", line 35, in list
    products_data=cache.get(key)
  File "/home/dani/gamingzone/ven/lib/python3.10/site-packages/django_redis/cache.py", line 92, in get
    value = self._get(key, default, version, client)
  File "/home/dani/gamingzone/ven/lib/python3.10/site-packages/django_redis/cache.py", line 36, in _decorator
    raise e.__cause__
  File "/home/dani/gamingzone/ven/lib/python3.10/site-packages/django_redis/client/default.py", line 258, in get
    value = client.get(key)
  File "/home/dani/gamingzone/ven/lib/python3.10/site-packages/redis/commands/core.py", line 1830, in get
    return self.execute_command("GET", name)
  File "/home/dani/gamingzone/ven/lib/python3.10/site-packages/redis/client.py", line 542, in execute_command
    conn = self.connection or pool.get_connection(command_name, **options)
  File "/home/dani/gamingzone/ven/lib/python3.10/site-packages/redis/connection.py", line 1109, in get_connection
    connection.connect()
  File "/home/dani/gamingzone/ven/lib/python3.10/site-packages/redis/connection.py", line 282, in connect
    raise ConnectionError(self._error_message(e))
redis.exceptions.ConnectionError: Error 111 connecting to 127.0.0.1:6379. Connection refused.
/home/dani/gamingzone/ven/lib/python3.10/site-packages/django/views/debug.py:487: ExceptionCycleWarning: Cycle in the exception chain detected: exception 'Error 111 connecting to 127.0.0.1:6379. Connection refused.' encountered again.
  warnings.warn(
Internal Server Error: /api/getProducts/
Traceback (most recent call last):
  File "/home/dani/gamingzone/ven/lib/python3.10/site-packages/django_redis/cache.py", line 29, in _decorator
    return method(self, *args, **kwargs)
  File "/home/dani/gamingzone/ven/lib/python3.10/site-packages/django_redis/cache.py", line 99, in _get
    return self.client.get(key, default=default, version=version, client=client)
  File "/home/dani/gamingzone/ven/lib/python3.10/site-packages/django_redis/client/default.py", line 260, in get
    raise ConnectionInterrupted(connection=client) from e
django_redis.exceptions.ConnectionInterrupted: Redis ConnectionError: Error 111 connecting to 127.0.0.1:6379. Connection refused.

During handling of the above exception, another exception occurred:

Traceback (most recent call last):
  File "/home/dani/gamingzone/ven/lib/python3.10/site-packages/django/core/handlers/exception.py", line 55, in inner
    response = get_response(request)
  File "/home/dani/gamingzone/ven/lib/python3.10/site-packages/django/core/handlers/base.py", line 197, in _get_response
    response = wrapped_callback(request, *callback_args, **callback_kwargs)
  File "/home/dani/gamingzone/ven/lib/python3.10/site-packages/django/views/decorators/csrf.py", line 56, in wrapper_view
    return view_func(*args, **kwargs)
  File "/home/dani/gamingzone/ven/lib/python3.10/site-packages/rest_framework/viewsets.py", line 124, in view
    return self.dispatch(request, *args, **kwargs)
  File "/home/dani/gamingzone/ven/lib/python3.10/site-packages/rest_framework/views.py", line 509, in dispatch
    response = self.handle_exception(exc)
  File "/home/dani/gamingzone/ven/lib/python3.10/site-packages/rest_framework/views.py", line 469, in handle_exception
    self.raise_uncaught_exception(exc)
  File "/home/dani/gamingzone/ven/lib/python3.10/site-packages/rest_framework/views.py", line 480, in raise_uncaught_exception
    raise exc
  File "/home/dani/gamingzone/ven/lib/python3.10/site-packages/rest_framework/views.py", line 506, in dispatch
    response = handler(request, *args, **kwargs)
  File "/home/dani/gamingzone/gamingzo/gzBackend/backendAPI/views.py", line 35, in list
    products_data=cache.get(key)
  File "/home/dani/gamingzone/ven/lib/python3.10/site-packages/django_redis/cache.py", line 92, in get
    value = self._get(key, default, version, client)
  File "/home/dani/gamingzone/ven/lib/python3.10/site-packages/django_redis/cache.py", line 36, in _decorator
    raise e.__cause__
  File "/home/dani/gamingzone/ven/lib/python3.10/site-packages/django_redis/client/default.py", line 258, in get
    value = client.get(key)
  File "/home/dani/gamingzone/ven/lib/python3.10/site-packages/redis/commands/core.py", line 1830, in get
    return self.execute_command("GET", name)
  File "/home/dani/gamingzone/ven/lib/python3.10/site-packages/redis/client.py", line 542, in execute_command
    conn = self.connection or pool.get_connection(command_name, **options)
  File "/home/dani/gamingzone/ven/lib/python3.10/site-packages/redis/connection.py", line 1119, in get_connection
    connection.connect()
  File "/home/dani/gamingzone/ven/lib/python3.10/site-packages/redis/connection.py", line 282, in connect
    raise ConnectionError(self._error_message(e))
redis.exceptions.ConnectionError: Error 111 connecting to 127.0.0.1:6379. Connection refused.
/home/dani/gamingzone/ven/lib/python3.10/site-packages/django/views/debug.py:487: ExceptionCycleWarning: Cycle in the exception chain detected: exception 'Error 111 connecting to 127.0.0.1:6379. Connection refused.' encountered again.
  warnings.warn(
Internal Server Error: /api/getProducts/
Traceback (most recent call last):
  File "/home/dani/gamingzone/ven/lib/python3.10/site-packages/django_redis/cache.py", line 29, in _decorator
    return method(self, *args, **kwargs)
  File "/home/dani/gamingzone/ven/lib/python3.10/site-packages/django_redis/cache.py", line 99, in _get
    return self.client.get(key, default=default, version=version, client=client)
  File "/home/dani/gamingzone/ven/lib/python3.10/site-packages/django_redis/client/default.py", line 260, in get
    raise ConnectionInterrupted(connection=client) from e
django_redis.exceptions.ConnectionInterrupted: Redis ConnectionError: Error 111 connecting to 127.0.0.1:6379. Connection refused.

During handling of the above exception, another exception occurred:

Traceback (most recent call last):
  File "/home/dani/gamingzone/ven/lib/python3.10/site-packages/django/core/handlers/exception.py", line 55, in inner
    response = get_response(request)
  File "/home/dani/gamingzone/ven/lib/python3.10/site-packages/django/core/handlers/base.py", line 197, in _get_response
    response = wrapped_callback(request, *callback_args, **callback_kwargs)
  File "/home/dani/gamingzone/ven/lib/python3.10/site-packages/django/views/decorators/csrf.py", line 56, in wrapper_view
    return view_func(*args, **kwargs)
  File "/home/dani/gamingzone/ven/lib/python3.10/site-packages/rest_framework/viewsets.py", line 124, in view
    return self.dispatch(request, *args, **kwargs)
  File "/home/dani/gamingzone/ven/lib/python3.10/site-packages/rest_framework/views.py", line 509, in dispatch
    response = self.handle_exception(exc)
  File "/home/dani/gamingzone/ven/lib/python3.10/site-packages/rest_framework/views.py", line 469, in handle_exception
    self.raise_uncaught_exception(exc)
  File "/home/dani/gamingzone/ven/lib/python3.10/site-packages/rest_framework/views.py", line 480, in raise_uncaught_exception
    raise exc
  File "/home/dani/gamingzone/ven/lib/python3.10/site-packages/rest_framework/views.py", line 506, in dispatch
    response = handler(request, *args, **kwargs)
  File "/home/dani/gamingzone/gamingzo/gzBackend/backendAPI/views.py", line 35, in list
    products_data=cache.get(key)
  File "/home/dani/gamingzone/ven/lib/python3.10/site-packages/django_redis/cache.py", line 92, in get
    value = self._get(key, default, version, client)
  File "/home/dani/gamingzone/ven/lib/python3.10/site-packages/django_redis/cache.py", line 36, in _decorator
    raise e.__cause__
  File "/home/dani/gamingzone/ven/lib/python3.10/site-packages/django_redis/client/default.py", line 258, in get
    value = client.get(key)
  File "/home/dani/gamingzone/ven/lib/python3.10/site-packages/redis/commands/core.py", line 1830, in get
    return self.execute_command("GET", name)
  File "/home/dani/gamingzone/ven/lib/python3.10/site-packages/redis/client.py", line 542, in execute_command
    conn = self.connection or pool.get_connection(command_name, **options)
  File "/home/dani/gamingzone/ven/lib/python3.10/site-packages/redis/connection.py", line 1119, in get_connection
    connection.connect()
  File "/home/dani/gamingzone/ven/lib/python3.10/site-packages/redis/connection.py", line 282, in connect
    raise ConnectionError(self._error_message(e))
redis.exceptions.ConnectionError: Error 111 connecting to 127.0.0.1:6379. Connection refused.
/home/dani/gamingzone/ven/lib/python3.10/site-packages/django/views/debug.py:487: ExceptionCycleWarning: Cycle in the exception chain detected: exception 'Error 111 connecting to 127.0.0.1:6379. Connection refused.' encountered again.
  warnings.warn(
Internal Server Error: /api/getProducts/
Traceback (most recent call last):
  File "/home/dani/gamingzone/ven/lib/python3.10/site-packages/django_redis/cache.py", line 29, in _decorator
    return method(self, *args, **kwargs)
  File "/home/dani/gamingzone/ven/lib/python3.10/site-packages/django_redis/cache.py", line 99, in _get
    return self.client.get(key, default=default, version=version, client=client)
  File "/home/dani/gamingzone/ven/lib/python3.10/site-packages/django_redis/client/default.py", line 260, in get
    raise ConnectionInterrupted(connection=client) from e
django_redis.exceptions.ConnectionInterrupted: Redis ConnectionError: Error 111 connecting to 127.0.0.1:6379. Connection refused.

During handling of the above exception, another exception occurred:

Traceback (most recent call last):
  File "/home/dani/gamingzone/ven/lib/python3.10/site-packages/django/core/handlers/exception.py", line 55, in inner
    response = get_response(request)
  File "/home/dani/gamingzone/ven/lib/python3.10/site-packages/django/core/handlers/base.py", line 197, in _get_response
    response = wrapped_callback(request, *callback_args, **callback_kwargs)
  File "/home/dani/gamingzone/ven/lib/python3.10/site-packages/django/views/decorators/csrf.py", line 56, in wrapper_view
    return view_func(*args, **kwargs)
  File "/home/dani/gamingzone/ven/lib/python3.10/site-packages/rest_framework/viewsets.py", line 124, in view
    return self.dispatch(request, *args, **kwargs)
  File "/home/dani/gamingzone/ven/lib/python3.10/site-packages/rest_framework/views.py", line 509, in dispatch
    response = self.handle_exception(exc)
  File "/home/dani/gamingzone/ven/lib/python3.10/site-packages/rest_framework/views.py", line 469, in handle_exception
    self.raise_uncaught_exception(exc)
  File "/home/dani/gamingzone/ven/lib/python3.10/site-packages/rest_framework/views.py", line 480, in raise_uncaught_exception
    raise exc
  File "/home/dani/gamingzone/ven/lib/python3.10/site-packages/rest_framework/views.py", line 506, in dispatch
    response = handler(request, *args, **kwargs)
  File "/home/dani/gamingzone/gamingzo/gzBackend/backendAPI/views.py", line 35, in list
    products_data=cache.get(key)
  File "/home/dani/gamingzone/ven/lib/python3.10/site-packages/django_redis/cache.py", line 92, in get
    value = self._get(key, default, version, client)
  File "/home/dani/gamingzone/ven/lib/python3.10/site-packages/django_redis/cache.py", line 36, in _decorator
    raise e.__cause__
  File "/home/dani/gamingzone/ven/lib/python3.10/site-packages/django_redis/client/default.py", line 258, in get
    value = client.get(key)
  File "/home/dani/gamingzone/ven/lib/python3.10/site-packages/redis/commands/core.py", line 1830, in get
    return self.execute_command("GET", name)
  File "/home/dani/gamingzone/ven/lib/python3.10/site-packages/redis/client.py", line 542, in execute_command
    conn = self.connection or pool.get_connection(command_name, **options)
  File "/home/dani/gamingzone/ven/lib/python3.10/site-packages/redis/connection.py", line 1119, in get_connection
    connection.connect()
  File "/home/dani/gamingzone/ven/lib/python3.10/site-packages/redis/connection.py", line 282, in connect
    raise ConnectionError(self._error_message(e))
redis.exceptions.ConnectionError: Error 111 connecting to 127.0.0.1:6379. Connection refused.
